<mujoco model="arena">
  <asset>
    <texture type='skybox' builtin='gradient' rgb1='.4 .6 .8' rgb2='0 0 0' width='100' height='100'/>
    <texture name='groundplane' type='2d' builtin='checker' rgb1='.2 .3 .4' rgb2='.1 .2 .3' width='300' height='300' mark='edge' markrgb='.8 .8 .8'/>
    <material name='groundplane' texture='groundplane' texrepeat='5 5' texuniform='true' reflectance='.2'/>
  </asset>
  <default>
    <geom solimp="0.9 0.95 0.001 0.5 2" solref="0.005 1" condim="6" />
  </default>
  <worldbody>
    <camera name="default_view" mode="targetbody" target="panda/panda_gripper/panda_rightfinger" pos="1.244 -0.603 1.202"/>
    <geom name='ground' type='plane' size='2 2 2' material='groundplane'
        friction='0.4'/>
    <light directional='true' diffuse='.7 .7 .7' pos='1 .1 2' dir='0 -.1 -2' specular='.3 .3 .3' castshadow='true'/>
    <body pos="0.4 0. 0.37">
      <geom type="box" size="0.1 0.1 0.005" rgba="1 0 0 1"/>
      <geom pos="0 -0.075 0.01" type="box" size="0.1 0.025 0.005" rgba="0.5 0 0 1"/>
      <geom pos="0 0 0.01" type="box" size="0.025 0.05 0.005" rgba="0.5 0 0 1"/>
    </body>
    <body pos="0.45 0 0.4" >
      <geom type="box" size=".025 .025 .025"  rgba="1 0 0 1" />
      <joint type="slide" damping="50" axis="0 1 0" range="-0.075 0.075" />
      <joint type="slide" damping="50" axis="1 0 0" range="-0.125 0.025" />
    </body>
    <body pos="0.4 0.25 0.355">
      <geom type="box" size="0.1 0.1 0.005" rgba="0 0 1 1"/>
    </body>
    <body pos="0.4 0.25 0.4">
      <geom type="sphere" size="0.04" rgba="0 0 1 1" />
      <joint type="slide" axis="0 1 0" range="-0.1 0.1" />
      <joint type="slide" axis="1 0 0" range="-0.1 0.1" />
    </body>

    <body pos="0.5 -0.2 0.355">
      <geom type="box" size="0.05 0.05 0.005" rgba="0 1 0 1"/>
      <geom type="cylinder" pos="0 0 0.02" size="0.03 0.02" rgba="0.5 1 0.5 0.3" contype="0" conaffinity="0" group="1"/>
    </body>
    <body pos="0.5 -0.2 0.4">
      <geom type="cylinder" size="0.028 0.02" rgba="0 1 0 1" />
      <joint type="slide" axis="0 0 1" range="-0.02 0" damping="10.0" stiffness="100"/>
    </body>

    <body pos="0.3 -0.2 0.4">
        <geom type="capsule" fromto="-0.08 0 0 0.08 0 0" size="0.015" rgba="0 0.5 0 1"/>
        <geom type="cylinder" size="0.02 0.03" rgba="0 1 0 1"/>
        <joint type="hinge" axis="0 0 1" damping="10" armature="0.01"/>
    </body>

  </worldbody>
</mujoco>
